ERROR 2022-10-23 19:44:36,785 log 13352 1124 Internal Server Error: /user/accounts/login/
Traceback (most recent call last):
  File "C:\Server\Python3.10.7\lib\site-packages\django\core\handlers\exception.py", line 55, in inner
    response = get_response(request)
  File "C:\Server\Python3.10.7\lib\site-packages\django\core\handlers\base.py", line 220, in _get_response
    response = response.render()
  File "C:\Server\Python3.10.7\lib\site-packages\django\template\response.py", line 114, in render
    self.content = self.rendered_content
  File "C:\Server\Python3.10.7\lib\site-packages\django\template\response.py", line 92, in rendered_content
    return template.render(context, self._request)
  File "C:\Server\Python3.10.7\lib\site-packages\django\template\backends\django.py", line 62, in render
    return self.template.render(context)
  File "C:\Server\Python3.10.7\lib\site-packages\django\template\base.py", line 175, in render
    return self._render(context)
  File "C:\Server\Python3.10.7\lib\site-packages\django\test\utils.py", line 111, in instrumented_test_render
    return self.nodelist.render(context)
  File "C:\Server\Python3.10.7\lib\site-packages\django\template\base.py", line 1005, in render
    return SafeString("".join([node.render_annotated(context) for node in self]))
  File "C:\Server\Python3.10.7\lib\site-packages\django\template\base.py", line 1005, in <listcomp>
    return SafeString("".join([node.render_annotated(context) for node in self]))
  File "C:\Server\Python3.10.7\lib\site-packages\django\template\base.py", line 966, in render_annotated
    return self.render(context)
  File "C:\Server\Python3.10.7\lib\site-packages\django\template\loader_tags.py", line 157, in render
    return compiled_parent._render(context)
  File "C:\Server\Python3.10.7\lib\site-packages\django\test\utils.py", line 111, in instrumented_test_render
    return self.nodelist.render(context)
  File "C:\Server\Python3.10.7\lib\site-packages\django\template\base.py", line 1005, in render
    return SafeString("".join([node.render_annotated(context) for node in self]))
  File "C:\Server\Python3.10.7\lib\site-packages\django\template\base.py", line 1005, in <listcomp>
    return SafeString("".join([node.render_annotated(context) for node in self]))
  File "C:\Server\Python3.10.7\lib\site-packages\django\template\base.py", line 966, in render_annotated
    return self.render(context)
  File "C:\Server\Python3.10.7\lib\site-packages\django\template\loader_tags.py", line 63, in render
    result = block.nodelist.render(context)
  File "C:\Server\Python3.10.7\lib\site-packages\django\template\base.py", line 1005, in render
    return SafeString("".join([node.render_annotated(context) for node in self]))
  File "C:\Server\Python3.10.7\lib\site-packages\django\template\base.py", line 1005, in <listcomp>
    return SafeString("".join([node.render_annotated(context) for node in self]))
  File "C:\Server\Python3.10.7\lib\site-packages\django\template\base.py", line 966, in render_annotated
    return self.render(context)
  File "C:\Server\Python3.10.7\lib\site-packages\django\template\defaulttags.py", line 472, in render
    url = reverse(view_name, args=args, kwargs=kwargs, current_app=current_app)
  File "C:\Server\Python3.10.7\lib\site-packages\django\urls\base.py", line 88, in reverse
    return resolver._reverse_with_prefix(view, prefix, *args, **kwargs)
  File "C:\Server\Python3.10.7\lib\site-packages\django\urls\resolvers.py", line 828, in _reverse_with_prefix
    raise NoReverseMatch(msg)
django.urls.exceptions.NoReverseMatch: Reverse for 'password_reset' not found. 'password_reset' is not a valid view function or pattern name.
ERROR 2022-10-23 19:44:36,867 basehttp 13352 1124 "GET /user/accounts/login/ HTTP/1.1" 500 180589
ERROR 2022-10-23 19:50:15,930 log 4424 5756 Internal Server Error: /user/accounts/login/
Traceback (most recent call last):
  File "C:\Server\Python3.10.7\lib\site-packages\django\core\handlers\exception.py", line 55, in inner
    response = get_response(request)
  File "C:\Server\Python3.10.7\lib\site-packages\django\core\handlers\base.py", line 220, in _get_response
    response = response.render()
  File "C:\Server\Python3.10.7\lib\site-packages\django\template\response.py", line 114, in render
    self.content = self.rendered_content
  File "C:\Server\Python3.10.7\lib\site-packages\django\template\response.py", line 92, in rendered_content
    return template.render(context, self._request)
  File "C:\Server\Python3.10.7\lib\site-packages\django\template\backends\django.py", line 62, in render
    return self.template.render(context)
  File "C:\Server\Python3.10.7\lib\site-packages\django\template\base.py", line 175, in render
    return self._render(context)
  File "C:\Server\Python3.10.7\lib\site-packages\django\test\utils.py", line 111, in instrumented_test_render
    return self.nodelist.render(context)
  File "C:\Server\Python3.10.7\lib\site-packages\django\template\base.py", line 1005, in render
    return SafeString("".join([node.render_annotated(context) for node in self]))
  File "C:\Server\Python3.10.7\lib\site-packages\django\template\base.py", line 1005, in <listcomp>
    return SafeString("".join([node.render_annotated(context) for node in self]))
  File "C:\Server\Python3.10.7\lib\site-packages\django\template\base.py", line 966, in render_annotated
    return self.render(context)
  File "C:\Server\Python3.10.7\lib\site-packages\django\template\loader_tags.py", line 157, in render
    return compiled_parent._render(context)
  File "C:\Server\Python3.10.7\lib\site-packages\django\test\utils.py", line 111, in instrumented_test_render
    return self.nodelist.render(context)
  File "C:\Server\Python3.10.7\lib\site-packages\django\template\base.py", line 1005, in render
    return SafeString("".join([node.render_annotated(context) for node in self]))
  File "C:\Server\Python3.10.7\lib\site-packages\django\template\base.py", line 1005, in <listcomp>
    return SafeString("".join([node.render_annotated(context) for node in self]))
  File "C:\Server\Python3.10.7\lib\site-packages\django\template\base.py", line 966, in render_annotated
    return self.render(context)
  File "C:\Server\Python3.10.7\lib\site-packages\django\template\loader_tags.py", line 63, in render
    result = block.nodelist.render(context)
  File "C:\Server\Python3.10.7\lib\site-packages\django\template\base.py", line 1005, in render
    return SafeString("".join([node.render_annotated(context) for node in self]))
  File "C:\Server\Python3.10.7\lib\site-packages\django\template\base.py", line 1005, in <listcomp>
    return SafeString("".join([node.render_annotated(context) for node in self]))
  File "C:\Server\Python3.10.7\lib\site-packages\django\template\base.py", line 966, in render_annotated
    return self.render(context)
  File "C:\Server\Python3.10.7\lib\site-packages\django\template\defaulttags.py", line 472, in render
    url = reverse(view_name, args=args, kwargs=kwargs, current_app=current_app)
  File "C:\Server\Python3.10.7\lib\site-packages\django\urls\base.py", line 88, in reverse
    return resolver._reverse_with_prefix(view, prefix, *args, **kwargs)
  File "C:\Server\Python3.10.7\lib\site-packages\django\urls\resolvers.py", line 828, in _reverse_with_prefix
    raise NoReverseMatch(msg)
django.urls.exceptions.NoReverseMatch: Reverse for 'password_reset' not found. 'password_reset' is not a valid view function or pattern name.
ERROR 2022-10-23 19:50:16,007 basehttp 4424 5756 "GET /user/accounts/login/ HTTP/1.1" 500 180589
ERROR 2022-10-23 19:50:16,977 log 4424 5756 Internal Server Error: /user/accounts/login/
Traceback (most recent call last):
  File "C:\Server\Python3.10.7\lib\site-packages\django\core\handlers\exception.py", line 55, in inner
    response = get_response(request)
  File "C:\Server\Python3.10.7\lib\site-packages\django\core\handlers\base.py", line 220, in _get_response
    response = response.render()
  File "C:\Server\Python3.10.7\lib\site-packages\django\template\response.py", line 114, in render
    self.content = self.rendered_content
  File "C:\Server\Python3.10.7\lib\site-packages\django\template\response.py", line 92, in rendered_content
    return template.render(context, self._request)
  File "C:\Server\Python3.10.7\lib\site-packages\django\template\backends\django.py", line 62, in render
    return self.template.render(context)
  File "C:\Server\Python3.10.7\lib\site-packages\django\template\base.py", line 175, in render
    return self._render(context)
  File "C:\Server\Python3.10.7\lib\site-packages\django\test\utils.py", line 111, in instrumented_test_render
    return self.nodelist.render(context)
  File "C:\Server\Python3.10.7\lib\site-packages\django\template\base.py", line 1005, in render
    return SafeString("".join([node.render_annotated(context) for node in self]))
  File "C:\Server\Python3.10.7\lib\site-packages\django\template\base.py", line 1005, in <listcomp>
    return SafeString("".join([node.render_annotated(context) for node in self]))
  File "C:\Server\Python3.10.7\lib\site-packages\django\template\base.py", line 966, in render_annotated
    return self.render(context)
  File "C:\Server\Python3.10.7\lib\site-packages\django\template\loader_tags.py", line 157, in render
    return compiled_parent._render(context)
  File "C:\Server\Python3.10.7\lib\site-packages\django\test\utils.py", line 111, in instrumented_test_render
    return self.nodelist.render(context)
  File "C:\Server\Python3.10.7\lib\site-packages\django\template\base.py", line 1005, in render
    return SafeString("".join([node.render_annotated(context) for node in self]))
  File "C:\Server\Python3.10.7\lib\site-packages\django\template\base.py", line 1005, in <listcomp>
    return SafeString("".join([node.render_annotated(context) for node in self]))
  File "C:\Server\Python3.10.7\lib\site-packages\django\template\base.py", line 966, in render_annotated
    return self.render(context)
  File "C:\Server\Python3.10.7\lib\site-packages\django\template\loader_tags.py", line 63, in render
    result = block.nodelist.render(context)
  File "C:\Server\Python3.10.7\lib\site-packages\django\template\base.py", line 1005, in render
    return SafeString("".join([node.render_annotated(context) for node in self]))
  File "C:\Server\Python3.10.7\lib\site-packages\django\template\base.py", line 1005, in <listcomp>
    return SafeString("".join([node.render_annotated(context) for node in self]))
  File "C:\Server\Python3.10.7\lib\site-packages\django\template\base.py", line 966, in render_annotated
    return self.render(context)
  File "C:\Server\Python3.10.7\lib\site-packages\django\template\defaulttags.py", line 472, in render
    url = reverse(view_name, args=args, kwargs=kwargs, current_app=current_app)
  File "C:\Server\Python3.10.7\lib\site-packages\django\urls\base.py", line 88, in reverse
    return resolver._reverse_with_prefix(view, prefix, *args, **kwargs)
  File "C:\Server\Python3.10.7\lib\site-packages\django\urls\resolvers.py", line 828, in _reverse_with_prefix
    raise NoReverseMatch(msg)
django.urls.exceptions.NoReverseMatch: Reverse for 'password_reset' not found. 'password_reset' is not a valid view function or pattern name.
ERROR 2022-10-23 19:50:17,043 basehttp 4424 5756 "GET /user/accounts/login/ HTTP/1.1" 500 180589
ERROR 2022-10-23 19:50:18,267 log 4424 4796 Internal Server Error: /user/accounts/login/
Traceback (most recent call last):
  File "C:\Server\Python3.10.7\lib\site-packages\django\core\handlers\exception.py", line 55, in inner
    response = get_response(request)
  File "C:\Server\Python3.10.7\lib\site-packages\django\core\handlers\base.py", line 220, in _get_response
    response = response.render()
  File "C:\Server\Python3.10.7\lib\site-packages\django\template\response.py", line 114, in render
    self.content = self.rendered_content
  File "C:\Server\Python3.10.7\lib\site-packages\django\template\response.py", line 92, in rendered_content
    return template.render(context, self._request)
  File "C:\Server\Python3.10.7\lib\site-packages\django\template\backends\django.py", line 62, in render
    return self.template.render(context)
  File "C:\Server\Python3.10.7\lib\site-packages\django\template\base.py", line 175, in render
    return self._render(context)
  File "C:\Server\Python3.10.7\lib\site-packages\django\test\utils.py", line 111, in instrumented_test_render
    return self.nodelist.render(context)
  File "C:\Server\Python3.10.7\lib\site-packages\django\template\base.py", line 1005, in render
    return SafeString("".join([node.render_annotated(context) for node in self]))
  File "C:\Server\Python3.10.7\lib\site-packages\django\template\base.py", line 1005, in <listcomp>
    return SafeString("".join([node.render_annotated(context) for node in self]))
  File "C:\Server\Python3.10.7\lib\site-packages\django\template\base.py", line 966, in render_annotated
    return self.render(context)
  File "C:\Server\Python3.10.7\lib\site-packages\django\template\loader_tags.py", line 157, in render
    return compiled_parent._render(context)
  File "C:\Server\Python3.10.7\lib\site-packages\django\test\utils.py", line 111, in instrumented_test_render
    return self.nodelist.render(context)
  File "C:\Server\Python3.10.7\lib\site-packages\django\template\base.py", line 1005, in render
    return SafeString("".join([node.render_annotated(context) for node in self]))
  File "C:\Server\Python3.10.7\lib\site-packages\django\template\base.py", line 1005, in <listcomp>
    return SafeString("".join([node.render_annotated(context) for node in self]))
  File "C:\Server\Python3.10.7\lib\site-packages\django\template\base.py", line 966, in render_annotated
    return self.render(context)
  File "C:\Server\Python3.10.7\lib\site-packages\django\template\loader_tags.py", line 63, in render
    result = block.nodelist.render(context)
  File "C:\Server\Python3.10.7\lib\site-packages\django\template\base.py", line 1005, in render
    return SafeString("".join([node.render_annotated(context) for node in self]))
  File "C:\Server\Python3.10.7\lib\site-packages\django\template\base.py", line 1005, in <listcomp>
    return SafeString("".join([node.render_annotated(context) for node in self]))
  File "C:\Server\Python3.10.7\lib\site-packages\django\template\base.py", line 966, in render_annotated
    return self.render(context)
  File "C:\Server\Python3.10.7\lib\site-packages\django\template\defaulttags.py", line 472, in render
    url = reverse(view_name, args=args, kwargs=kwargs, current_app=current_app)
  File "C:\Server\Python3.10.7\lib\site-packages\django\urls\base.py", line 88, in reverse
    return resolver._reverse_with_prefix(view, prefix, *args, **kwargs)
  File "C:\Server\Python3.10.7\lib\site-packages\django\urls\resolvers.py", line 828, in _reverse_with_prefix
    raise NoReverseMatch(msg)
django.urls.exceptions.NoReverseMatch: Reverse for 'password_reset' not found. 'password_reset' is not a valid view function or pattern name.
ERROR 2022-10-23 19:50:18,331 basehttp 4424 4796 "GET /user/accounts/login/ HTTP/1.1" 500 180854
